Workbook

Sheet Produccion
D3: Año | E3: Basicos | F3: % Basicos | G3: Intermedios | H3: % Intermedios | I3: Finales | J3: % Finales | K3: Total
D4: 2015 | E4: 2435900 | F4: 42 | G4: 809000 | H4: 13.9 | I4: 2559800 | J4: 44.1 | K4: 5804700
D5: 2016 | E5: 2606500 | F5: 41.8 | G5: 819600 | H5: 13.2 | I5: 2799000 | J5: 45 | K5: 6225100
D6: 2017 | E6: 2546700 | F6: 39.9 | G6: 749100 | H6: 11.7 | I6: 3092800 | J6: 48.4 | K6: 6388600
D7: 2018 | E7: 2366500 | F7: 41.8 | G7: 692100 | H7: 12.2 | I7: 2602200 | J7: 46 | K7: 5660800
D8: 2019 | E8: 2238100 | F8: 41.7 | G8: 613200 | H8: 11.4 | I8: 2521800 | J8: 46.9 | K8: 5373100
D9: 2020 | E9: 2176600 | F9: 39.7 | G9: 588500 | H9: 10.7 | I9: 2718700 | J9: 49.6 | K9: 5483800
D10: 2021 | E10: 2161200 | F10: 40.9 | G10: 679700 | H10: 12.8 | I10: 2447200 | J10: 46.3 | K10: 5288100
D11: 2022 | E11: 2566300 | F11: 40.3 | G11: 740600 | H11: 11.6 | I11: 3060600 | J11: 48.1 | K11: 6367500
D12: 2023 | E12: 2454900 | F12: 40.3 | G12: 701100 | H12: 11.5 | I12: 2940100 | J12: 48.2 | K12: 6096100
D13: 2024 | E13: 2485000 | F13: 41.9 | G13: 642700 | H13: 10.8 | I13: 2808900 | J13: 47.3 | K13: 5936600
D15: Produccion expresada en millones de toneladas | J15: Grafico 1
D16: Año | E16: Basicos | F16: Intermedios | G16: Finales | H16: Total
D17: 2015 | E17: =E4/1000000 -> 2.4359 | F17: =G4/1000000 -> 0.809 | G17: =I4/1000000 -> 2.5598 | H17: =K4/1000000 -> 5.8047
D18: 2016 | E18: =E5/1000000 -> 2.6065 | F18: =G5/1000000 -> 0.8196 | G18: =I5/1000000 -> 2.799 | H18: =K5/1000000 -> 6.2251
D19: 2017 | E19: =E6/1000000 -> 2.5467 | F19: =G6/1000000 -> 0.7491 | G19: =I6/1000000 -> 3.0928 | H19: =K6/1000000 -> 6.3886
D20: 2018 | E20: =E7/1000000 -> 2.3665 | F20: =G7/1000000 -> 0.6921 | G20: =I7/1000000 -> 2.6022 | H20: =K7/1000000 -> 5.6608
D21: 2019 | E21: =E8/1000000 -> 2.2381 | F21: =G8/1000000 -> 0.6132 | G21: =I8/1000000 -> 2.5218 | H21: =K8/1000000 -> 5.3731
D22: 2020 | E22: =E9/1000000 -> 2.1766 | F22: =G9/1000000 -> 0.5885 | G22: =I9/1000000 -> 2.7187 | H22: =K9/1000000 -> 5.4838
D23: 2021 | E23: =E10/1000000 -> 2.1612 | F23: =G10/1000000 -> 0.6797 | G23: =I10/1000000 -> 2.4472 | H23: =K10/1000000 -> 5.2881
D24: 2022 | E24: =E11/1000000 -> 2.5663 | F24: =G11/1000000 -> 0.7406 | G24: =I11/1000000 -> 3.0606 | H24: =K11/1000000 -> 6.3675
D25: 2023 | E25: =E12/1000000 -> 2.4549 | F25: =G12/1000000 -> 0.7011 | G25: =I12/1000000 -> 2.9401 | H25: =K12/1000000 -> 6.0961
D26: 2024 | E26: =E13/1000000 -> 2.485 | F26: =G13/1000000 -> 0.6427 | G26: =I13/1000000 -> 2.8089 | H26: =K13/1000000 -> 5.9366

Sheet Capacidad instalada 2024
B2: Capacidad instalada de productos petroquimicos 2024 | K2: Capacidad instalada por ciudad | P2: Capacidad instalada por provincia
B3: Producto Petroquimico | C3: Planta | D3: Ciudad | E3: Provincia | F3: Tipo de producto | G3: Valor | H3: Capacidad instalada activa | I3: Plantas inactivas/cerradas | K3: Ciudad | L3: Capacidad instalada | M3: % del total | P3: Provincia | Q3: Capacidad instalada | R3: % del total
B4: ABS | F4: =IF(COUNTIF($K$30:$K$41, B4)>0, "Básico", IF(COUNTIF($L$30:$L$71, B4)>0, "Intermedio", IF(COUNTIF('Capacidad instalada 2024'!$M$30:$M$73, B4)>0, "Final", "No encontrado"))) -> Final | K4: Bahia Blanca | L4: =SUMIF(D$4:D$151,K4,H$4:H$151) -> 4352000 | M4: =L4/L$24 -> 0.56287168 | P4: Bs As | Q4: =SUMIF(E$4:E$151,P4,H$4:H$151) -> 5867500 | R4: =Q4/Q$12 -> 0.75888088
B5: ACETALDEHÍDO | C5: ATANOR S.C.A | D5: Baradero | E5: Bs As | F5: =IF(COUNTIF($K$30:$K$41, B5)>0, "Básico", IF(COUNTIF($L$30:$L$71, B5)>0, "Intermedio", IF(COUNTIF('Capacidad instalada 2024'!$M$30:$M$73, B5)>0, "Final", "No encontrado"))) -> Intermedio | H5: Cerro | I5: 9000 | K5: Baradero | L5: =SUMIF(D$4:D$151,K5,H$4:H$151) -> 0 | M5: =L5/L$24 -> 0 | P5: Cordoba | Q5: =SUMIF(E$4:E$151,P5,H$4:H$151) -> 47300 | R5: =Q5/Q$12 -> 0.0061176081
B6: ACETATO DE n-BUTILO | C6: ATANOR S.C.A | D6: Baradero | E6: Bs As | F6: =IF(COUNTIF($K$30:$K$41, B6)>0, "Básico", IF(COUNTIF($L$30:$L$71, B6)>0, "Intermedio", IF(COUNTIF('Capacidad instalada 2024'!$M$30:$M$73, B6)>0, "Final", "No encontrado"))) -> Final | H6: Cerro | I6: 6000 | K6: Berazategui | L6: =SUMIF(D$4:D$151,K6,H$4:H$151) -> 0 | M6: =L6/L$24 -> 0 | P6: Salta | Q6: =SUMIF(E$4:E$151,P6,H$4:H$151) -> 204000 | R6: =Q6/Q$12 -> 0.02638461
B7: ACETATO DE ETILO | C7: ATANOR S.C.A | D7: Baradero | E7: Bs As | F7: =IF(COUNTIF($K$30:$K$41, B7)>0, "Básico", IF(COUNTIF($L$30:$L$71, B7)>0, "Intermedio", IF(COUNTIF('Capacidad instalada 2024'!$M$30:$M$73, B7)>0, "Final", "No encontrado"))) -> Final | H7: Cerro | I7: 28000 | K7: Campana | L7: =SUMIF(D$4:D$151,K7,H$4:H$151) -> 246700 | M7: =L7/L$24 -> 0.031907271 | P7: San Luis | Q7: =SUMIF(E$4:E$151,P7,H$4:H$151) -> 30730 | R7: =Q7/Q$12 -> 0.0039745052
B8: ACETATO DE VINILO | F8: =IF(COUNTIF($K$30:$K$41, B8)>0, "Básico", IF(COUNTIF($L$30:$L$71, B8)>0, "Intermedio", IF(COUNTIF('Capacidad instalada 2024'!$M$30:$M$73, B8)>0, "Final", "No encontrado"))) -> Intermedio | K8: Concordia | L8: =SUMIF(D$4:D$151,K8,H$4:H$151) -> 67850 | M8: =L8/L$24 -> 0.0087754696 | P8: Santa Fe | Q8: =SUMIF(E$4:E$151,P8,H$4:H$151) -> 935400 | R8: =Q8/Q$12 -> 0.1209812
B9: ACETONA | C9: CARBOCLOR S.A. | D9: Campana | E9: Bs As | F9: =IF(COUNTIF($K$30:$K$41, B9)>0, "Básico", IF(COUNTIF($L$30:$L$71, B9)>0, "Intermedio", IF(COUNTIF('Capacidad instalada 2024'!$M$30:$M$73, B9)>0, "Final", "No encontrado"))) -> Intermedio | H9: Inactiva | I9: 18000 | K9: El Galpon | L9: =SUMIF(D$4:D$151,K9,H$4:H$151) -> 204000 | M9: =L9/L$24 -> 0.02638461 | P9: Entre Rios | Q9: =SUMIF(E$4:E$151,P9,H$4:H$151) -> 67850 | R9: =Q9/Q$12 -> 0.0087754696
B10: Ácido acético | C10: ATANOR S.C.A Rio Tercero | D10: Rio Tercero | E10: Cordoba | F10: =IF(COUNTIF($K$30:$K$41, B10)>0, "Básico", IF(COUNTIF($L$30:$L$71, B10)>0, "Intermedio", IF(COUNTIF('Capacidad instalada 2024'!$M$30:$M$73, B10)>0, "Final", "No encontrado"))) -> Intermedio | H10: Cerro | I10: 3600 | K10: Ensenada | L10: =SUMIF(D$4:D$151,K10,H$4:H$151) -> 991500 | M10: =L10/L$24 -> 0.12823696 | P10: Neuquen | Q10: =SUMIF(E$4:E$151,P10,H$4:H$151) -> 411000 | R10: =Q10/Q$12 -> 0.053157229
B11: Ácido acético | D11: Baradero | E11: Bs As | F11: =IF(COUNTIF($K$30:$K$41, B11)>0, "Básico", IF(COUNTIF($L$30:$L$71, B11)>0, "Intermedio", IF(COUNTIF('Capacidad instalada 2024'!$M$30:$M$73, B11)>0, "Final", "No encontrado"))) -> Intermedio | H11: Cerro | I11: 12000 | K11: General Lagos | L11: =SUMIF(D$4:D$151,K11,H$4:H$151) -> 20000 | M11: =L11/L$24 -> 0.0025867265 | P11: Mendoza | Q11: =SUMIF(E$4:E$151,P11,H$4:H$151) -> 168000 | R11: =Q11/Q$12 -> 0.021728502
B12: ÁCIDO ACRÍLICO Y SUS ÉSTERES | F12: Intermedio | K12: Lujan de Cuyo | L12: =SUMIF(D$4:D$151,K12,H$4:H$151) -> 168000 | M12: =L12/L$24 -> 0.021728502 | P12: Total | Q12: =SUM(Q4:Q11) -> 7731780 | R12: =SUM(R4:R11) -> 1
B13: ÁCIDO ADÍPICO | F13: =IF(COUNTIF($K$30:$K$41, B13)>0, "Básico", IF(COUNTIF($L$30:$L$71, B13)>0, "Intermedio", IF(COUNTIF('Capacidad instalada 2024'!$M$30:$M$73, B13)>0, "Final", "No encontrado"))) -> Intermedio | K13: Munro | L13: =SUMIF(D$4:D$151,K13,H$4:H$151) -> 0 | M13: =L13/L$24 -> 0
B14: ÁCIDO BENZOICO | C14: PETROQUIMICA ARGENTINA S.A. | D14: San Miguel del Monte | E14: Bs As | F14: =IF(COUNTIF($K$30:$K$41, B14)>0, "Básico", IF(COUNTIF($L$30:$L$71, B14)>0, "Intermedio", IF(COUNTIF('Capacidad instalada 2024'!$M$30:$M$73, B14)>0, "Final", "No encontrado"))) -> Intermedio | H14: 2300 | K14: Olmos | L14: =SUMIF(D$4:D$151,K14,H$4:H$151) -> 0 | M14: =L14/L$24 -> 0 | P14: Capacidad instalada Provincia de Buenos Aires
B15: ÁCIDO CÍTRICO | F15: =IF(COUNTIF($K$30:$K$41, B15)>0, "Básico", IF(COUNTIF($L$30:$L$71, B15)>0, "Intermedio", IF(COUNTIF('Capacidad instalada 2024'!$M$30:$M$73, B15)>0, "Final", "No encontrado"))) -> No encontrado | K15: P. Huincul | L15: =SUMIF(D$4:D$151,K15,H$4:H$151) -> 411000 | M15: =L15/L$24 -> 0.053157229 | P15: Ciudad | Q15: Capacidad instalada | R15: % del total
B16: ÁCIDO 2-ETILHEXANOICO | F16: =IF(COUNTIF($K$30:$K$41, B16)>0, "Básico", IF(COUNTIF($L$30:$L$71, B16)>0, "Intermedio", IF(COUNTIF('Capacidad instalada 2024'!$M$30:$M$73, B16)>0, "Final", "No encontrado"))) -> No encontrado | K16: Puerto Galvan | L16: =SUMIF(D$4:D$151,K16,H$4:H$151) -> 0 | M16: =L16/L$24 -> 0 | P16: Bahia Blanca | Q16: =SUMIF(D$4:D$151,P16,H$4:H$151) -> 4352000 | R16: =Q16/Q$26 -> 0.74171282
B17: ÁCIDO FÓRMICO | F17: =IF(COUNTIF($K$30:$K$41, B17)>0, "Básico", IF(COUNTIF($L$30:$L$71, B17)>0, "Intermedio", IF(COUNTIF('Capacidad instalada 2024'!$M$30:$M$73, B17)>0, "Final", "No encontrado"))) -> Intermedio | K17: Puerto General San Martin | L17: =SUMIF(D$4:D$151,K17,H$4:H$151) -> 880900 | M17: =L17/L$24 -> 0.11393237 | P17: Baradero | Q17: =SUMIF(D$4:D$151,P17,H$4:H$151) -> 0 | R17: =Q17/Q$26 -> 0
B18: ÁCIDO FUMÁRICO | F18: =IF(COUNTIF($K$30:$K$41, B18)>0, "Básico", IF(COUNTIF($L$30:$L$71, B18)>0, "Intermedio", IF(COUNTIF('Capacidad instalada 2024'!$M$30:$M$73, B18)>0, "Final", "No encontrado"))) -> Intermedio | K18: Rio Tercero | L18: =SUMIF(D$4:D$151,K18,H$4:H$151) -> 47300 | M18: =L18/L$24 -> 0.0061176081 | P18: Campana | Q18: =SUMIF(D$4:D$151,P18,H$4:H$151) -> 246700 | R18: =Q18/Q$26 -> 0.042045164
B19: ÁCIDO NÍTRICO | C19: AUSTIN POWDER ARGENTINA S.A. | D19: El Galpon | E19: Salta | F19: =IF(COUNTIF($K$30:$K$41, B19)>0, "Básico", IF(COUNTIF($L$30:$L$71, B19)>0, "Intermedio", IF(COUNTIF('Capacidad instalada 2024'!$M$30:$M$73, B19)>0, "Final", "No encontrado"))) -> Intermedio | H19: 60000 | K19: San Lorenzo | L19: =SUMIF(D$4:D$151,K19,H$4:H$151) -> 34500 | M19: =L19/L$24 -> 0.0044621032 | P19: Ensenada | Q19: =SUMIF(D$4:D$151,P19,H$4:H$151) -> 991500 | R19: =Q19/Q$26 -> 0.16898168
B20: ÁCIDO NÍTRICO | C20: FÁBRICA MILITAR RÍO TERCERO | D20: Rio Tercero | E20: Cordoba | F20: =IF(COUNTIF($K$30:$K$41, B20)>0, "Básico", IF(COUNTIF($L$30:$L$71, B20)>0, "Intermedio", IF(COUNTIF('Capacidad instalada 2024'!$M$30:$M$73, B20)>0, "Final", "No encontrado"))) -> Intermedio | H20: 39000 | K20: San Luis | L20: =SUMIF(D$4:D$151,K20,H$4:H$151) -> 20000 | M20: =L20/L$24 -> 0.0025867265 | P20: Munro | Q20: =SUMIF(D$4:D$151,P20,H$4:H$151) -> 0 | R20: =Q20/Q$26 -> 0
B21: ÁCIDO NÍTRICO | C21: FRÍO INDUSTRIAS ARGENTINAS S.A | D21: Villa Mercedes | E21: San Luis | F21: =IF(COUNTIF($K$30:$K$41, B21)>0, "Básico", IF(COUNTIF($L$30:$L$71, B21)>0, "Intermedio", IF(COUNTIF('Capacidad instalada 2024'!$M$30:$M$73, B21)>0, "Final", "No encontrado"))) -> Intermedio | H21: 10730 | K21: San Miguel del Monte | L21: =SUMIF(D$4:D$151,K21,H$4:H$151) -> 2300 | M21: =L21/L$24 -> 0.00029747354 | P21: San Miguel del Monte | Q21: =SUMIF(D$4:D$151,P21,H$4:H$151) -> 2300 | R21: =Q21/Q$26 -> 0.00039198977
B22: ÁCIDO OXÁLICO | F22: =IF(COUNTIF($K$30:$K$41, B22)>0, "Básico", IF(COUNTIF($L$30:$L$71, B22)>0, "Intermedio", IF(COUNTIF('Capacidad instalada 2024'!$M$30:$M$73, B22)>0, "Final", "No encontrado"))) -> No encontrado | K22: Villa Mercedes | L22: =SUMIF(D$4:D$151,K22,H$4:H$151) -> 10730 | M22: =L22/L$24 -> 0.0013877788 | P22: Berazategui | Q22: =SUMIF(D$4:D$151,P22,H$4:H$151) -> 0 | R22: =Q22/Q$26 -> 0
B23: ÁCIDO SALICÍLICO | F23: =IF(COUNTIF($K$30:$K$41, B23)>0, "Básico", IF(COUNTIF($L$30:$L$71, B23)>0, "Intermedio", IF(COUNTIF('Capacidad instalada 2024'!$M$30:$M$73, B23)>0, "Final", "No encontrado"))) -> Intermedio | K23: Zarate | L23: =SUMIF(D$4:D$151,K23,H$4:H$151) -> 275000 | M23: =L23/L$24 -> 0.035567489 | P23: Puerto Galvan | Q23: =SUMIF(D$4:D$151,P23,H$4:H$151) -> 0 | R23: =Q23/Q$26 -> 0
B24: ÁCIDO TEREFTÁLICO | F24: =IF(COUNTIF($K$30:$K$41, B24)>0, "Básico", IF(COUNTIF($L$30:$L$71, B24)>0, "Intermedio", IF(COUNTIF('Capacidad instalada 2024'!$M$30:$M$73, B24)>0, "Final", "No encontrado"))) -> Intermedio | K24: Total | L24: =SUM(L3:L23) -> 7731780 | M24: =L24/L$24 -> 1 | P24: Olmos | Q24: =SUMIF(D$4:D$151,P24,H$4:H$151) -> 0 | R24: =Q24/Q$26 -> 0
B25: ACRILONITRILO | F25: =IF(COUNTIF($K$30:$K$41, B25)>0, "Básico", IF(COUNTIF($L$30:$L$71, B25)>0, "Intermedio", IF(COUNTIF('Capacidad instalada 2024'!$M$30:$M$73, B25)>0, "Final", "No encontrado"))) -> Intermedio | P25: Zarate | Q25: =SUMIF(D$4:D$151,P25,H$4:H$151) -> 275000 | R25: =Q25/Q$26 -> 0.046868343
B26: Alcoholes de C7 a C13 | C26: YPF S.A. Ensenada | D26: Ensenada | E26: Bs As | F26: =IF(COUNTIF($K$30:$K$41, B26)>0, "Básico", IF(COUNTIF($L$30:$L$71, B26)>0, "Intermedio", IF(COUNTIF('Capacidad instalada 2024'!$M$30:$M$73, B26)>0, "Final", "No encontrado"))) -> Intermedio | H26: Cerro | I26: 35000 | P26: Total | Q26: =SUM(Q16:Q25) -> 5867500 | R26: =SUM(R16:R25) -> 1
B27: ALCOHOL POLIVINÍLICO | F27: =IF(COUNTIF($K$30:$K$41, B27)>0, "Básico", IF(COUNTIF($L$30:$L$71, B27)>0, "Intermedio", IF(COUNTIF('Capacidad instalada 2024'!$M$30:$M$73, B27)>0, "Final", "No encontrado"))) -> No encontrado
B28: ALQUILBENCENO LINEAL | C28: YPF S.A. Ensenada | D28: Ensenada | E28: Bs As | F28: =IF(COUNTIF($K$30:$K$41, B28)>0, "Básico", IF(COUNTIF($L$30:$L$71, B28)>0, "Intermedio", IF(COUNTIF('Capacidad instalada 2024'!$M$30:$M$73, B28)>0, "Final", "No encontrado"))) -> Intermedio | H28: 52000 | K28: Clasificacion de los productos petroquimicos
B29: AMONÍACO | C29: AUSTIN POWDER ARGENTINA S.A. | D29: El Galpon | E29: Salta | F29: =IF(COUNTIF($K$30:$K$41, B29)>0, "Básico", IF(COUNTIF($L$30:$L$71, B29)>0, "Intermedio", IF(COUNTIF('Capacidad instalada 2024'!$M$30:$M$73, B29)>0, "Final", "No encontrado"))) -> Básico | H29: 60000 | K29: Basicos | L29: Intermedios | M29: Finales
B30: AMONÍACO | C30: BUNGE ARGENTINA S.A. | D30: Campana | E30: Bs As | F30: =IF(COUNTIF($K$30:$K$41, B30)>0, "Básico", IF(COUNTIF($L$30:$L$71, B30)>0, "Intermedio", IF(COUNTIF('Capacidad instalada 2024'!$M$30:$M$73, B30)>0, "Final", "No encontrado"))) -> Básico | H30: 29700 | K30: Amoníaco | L30: Acetaldehído | M30: ABS | N30: =SUBSTITUTE(SUBSTITUTE(SUBSTITUTE(SUBSTITUTE(SUBSTITUTE(A1,"á","a"),"é","e"),"í","i"),"ó","o"),"ú","u")
B31: AMONÍACO | C31: PROFERTIL S.A. | D31: Bahia Blanca | E31: Bs As | F31: =IF(COUNTIF($K$30:$K$41, B31)>0, "Básico", IF(COUNTIF($L$30:$L$71, B31)>0, "Intermedio", IF(COUNTIF('Capacidad instalada 2024'!$M$30:$M$73, B31)>0, "Final", "No encontrado"))) -> Básico | H31: 790000 | K31: Benceno | L31: Acetato de vinilo | M31: Acetato de n-butilo
B32: ANHÍDRIDO ACÉTICO | C32: ATANOR S.C.A | D32: Baradero | E32: Bs As | F32: =IF(COUNTIF($K$30:$K$41, B32)>0, "Básico", IF(COUNTIF($L$30:$L$71, B32)>0, "Intermedio", IF(COUNTIF('Capacidad instalada 2024'!$M$30:$M$73, B32)>0, "Final", "No encontrado"))) -> No encontrado | H32: Cerro | I32: 2500 | K32: Butadieno | L32: Acetona | M32: Acetato de etilo
B33: Anhídrico ftalico | C33: VARTECO QUÍMICA PUNTANA S.A. | D33: San Lorenzo | E33: Santa Fe | F33: =IF(COUNTIF($K$30:$K$41, B33)>0, "Básico", IF(COUNTIF($L$30:$L$71, B33)>0, "Intermedio", IF(COUNTIF('Capacidad instalada 2024'!$M$30:$M$73, B33)>0, "Final", "No encontrado"))) -> Intermedio | H33: 17500 | K33: Buteno-1 | L33: Ácido acético | M33: Caucho acrilonitrilo-butadieno
B34: Anhídrico maleico | C34: YPF S.A. Ensenada | D34: Ensenada | E34: Bs As | F34: =IF(COUNTIF($K$30:$K$41, B34)>0, "Básico", IF(COUNTIF($L$30:$L$71, B34)>0, "Intermedio", IF(COUNTIF('Capacidad instalada 2024'!$M$30:$M$73, B34)>0, "Final", "No encontrado"))) -> Intermedio | H34: 17500 | K34: Butileno | L34: Ácido adípico | M34: Caucho butilo
B35: BENCENO | C35: PAMPA ENERGÍA S.A General San Martin | D35: Puerto General San Martin | E35: Santa Fe | F35: =IF(COUNTIF($K$30:$K$41, B35)>0, "Básico", IF(COUNTIF($L$30:$L$71, B35)>0, "Intermedio", IF(COUNTIF('Capacidad instalada 2024'!$M$30:$M$73, B35)>0, "Final", "No encontrado"))) -> Básico | K35: Etileno | L35: Ácido benzoico | M35: Caucho estireno-butadieno
B36: BENCENO | C36: YPF S.A. Ensenada | D36: Ensenada | E36: Bs As | F36: =IF(COUNTIF($K$30:$K$41, B36)>0, "Básico", IF(COUNTIF($L$30:$L$71, B36)>0, "Intermedio", IF(COUNTIF('Capacidad instalada 2024'!$M$30:$M$73, B36)>0, "Final", "No encontrado"))) -> Básico | K36: Metanol | L36: Ácido fórmico | M36: Caucho etileno-propileno
B37: BISFENOL A | F37: =IF(COUNTIF($K$30:$K$41, B37)>0, "Básico", IF(COUNTIF($L$30:$L$71, B37)>0, "Intermedio", IF(COUNTIF('Capacidad instalada 2024'!$M$30:$M$73, B37)>0, "Final", "No encontrado"))) -> Intermedio | K37: Propileno | L37: Ácido fumárico | M37: Caucho polibutadieno
B38: BUTADIENO | F38: =IF(COUNTIF($K$30:$K$41, B38)>0, "Básico", IF(COUNTIF($L$30:$L$71, B38)>0, "Intermedio", IF(COUNTIF('Capacidad instalada 2024'!$M$30:$M$73, B38)>0, "Final", "No encontrado"))) -> Básico | K38: Sulfuro de carbono | L38: Ácido nítrico | M38: Caucho policloropreno
B39: i-BUTANOL | F39: =IF(COUNTIF($K$30:$K$41, B39)>0, "Básico", IF(COUNTIF($L$30:$L$71, B39)>0, "Intermedio", IF(COUNTIF('Capacidad instalada 2024'!$M$30:$M$73, B39)>0, "Final", "No encontrado"))) -> Intermedio | K39: Tolueno | L39: Ácido salicílico | M39: Caucho poliisopreno
B40: n-BUTANOL | F40: =IF(COUNTIF($K$30:$K$41, B40)>0, "Básico", IF(COUNTIF($L$30:$L$71, B40)>0, "Intermedio", IF(COUNTIF('Capacidad instalada 2024'!$M$30:$M$73, B40)>0, "Final", "No encontrado"))) -> Intermedio | K40: o-Xileno | L40: Ácido tereftálico | M40: Cloruro de amonio
B41: BUTANOL SECUNDARIO | C41: CARBOCLOR S.A. | D41: Campana | E41: Bs As | F41: =IF(COUNTIF($K$30:$K$41, B41)>0, "Básico", IF(COUNTIF($L$30:$L$71, B41)>0, "Intermedio", IF(COUNTIF('Capacidad instalada 2024'!$M$30:$M$73, B41)>0, "Final", "No encontrado"))) -> Intermedio | H41: Inactiva | I41: 13000 | K41: Xilenos mezcla | L41: Acrilonitrilo | M41: Cloruro de metileno
...

Sheet Capacidad instalada 2021
B2: Capacidad instalada de productos petroquimicos 2021 | I2: Capacidad instalada por ciudad | N2: Capacidad instalada por provincia
B3: Producto Petroquimico | C3: Planta | D3: Ciudad | E3: Provincia | F3: Capacidad instalada activa | G3: Plantas inactivas/cerradas | I3: Ciudad | J3: Capacidad instalada | K3: % del total | N3: Provincia | O3: Capacidad instalada | P3: % del total
B4: ABS | I4: Bahia Blanca | J4: =SUMIF(D$4:D$152,I4,F$4:F$152) -> 4302000 | K4: =J4/J$28 -> 0.55767127 | N4: Bs As | O4: =SUMIF(E$4:E$152,N4,F$4:F$152) -> 5885292 | P4: =O4/O$12 -> 0.76316185
B5: ACETALDEHÍDO | C5: ATANOR S.C.A. | D5: Baradero | E5: Bs As | F5: Cerro | G5: 9000 | I5: Baradero | J5: =SUMIF(D$4:D$152,I5,F$4:F$152) -> 0 | K5: =J5/J$28 -> 0 | N5: Cordoba | O5: =SUMIF(E$4:E$152,N5,F$4:F$152) -> 74800 | P5: =O5/O$12 -> 0.0096995198
B6: ACETATO DE ETILO | C6: ATANOR S.C.A. | D6: Baradero | E6: Bs As | F6: Cerro | G6: 28000 | I6: Berazategui | J6: =SUMIF(D$4:D$152,I6,F$4:F$152) -> 0 | K6: =J6/J$28 -> 0 | N6: Salta | O6: =SUMIF(E$4:E$152,N6,F$4:F$152) -> 205000 | P6: =O6/O$12 -> 0.026582908
B7: ACETATO DE n-BUTILO | C7: ATANOR S.C.A. | D7: Baradero | E7: Bs As | F7: Cerro | G7: 6000 | I7: Burzaco | J7: =SUMIF(D$4:D$152,I7,F$4:F$152) -> 0 | K7: =J7/J$28 -> 0 | N7: San Luis | O7: =SUMIF(E$4:E$152,N7,F$4:F$152) -> 25730 | P7: =O7/O$12 -> 0.0033364792
B8: ACETATO DE VINILO | I8: Campana | J8: =SUMIF(D$4:D$152,I8,F$4:F$152) -> 246700 | K8: =J8/J$28 -> 0.031979894 | N8: Santa Fe | O8: =SUMIF(E$4:E$152,N8,F$4:F$152) -> 872900 | P8: =O8/O$12 -> 0.11319132
B9: ACETONA | C9: CARBOCLOR S.A. | D9: Campana | E9: Bs As | F9: Inactiva | G9: 18000 | I9: Concordia | J9: =SUMIF(D$4:D$152,I9,F$4:F$152) -> 59000 | K9: =J9/J$28 -> 0.0076482113 | N9: Entre Rios | O9: =SUMIF(E$4:E$152,N9,F$4:F$152) -> 59000 | P9: =O9/O$12 -> 0.0076506907
B10: ÁCIDO 2-ETILHEXANOICO | I10: El Galpon | J10: =SUMIF(D$4:D$152,I10,F$4:F$152) -> 205000 | K10: =J10/J$28 -> 0.026574294 | N10: Neuquen | O10: =SUMIF(E$4:E$152,N10,F$4:F$152) -> 411000 | P10: =O10/O$12 -> 0.05329549
B11: ÁCIDO ACÉTICO | C11: ATANOR S.C.A. | D11: Baradero | E11: Bs As | F11: Cerro | G11: 12000 | I11: Ensenada | J11: =SUMIF(D$4:D$152,I11,F$4:F$152) -> 1042500 | K11: =J11/J$28 -> 0.13514001 | N11: Mendoza | O11: =SUMIF(E$4:E$152,N11,F$4:F$152) -> 178000 | P11: =O11/O$12 -> 0.023081745
B12: ÁCIDO ACÉTICO | C12: ATANOR S.C.A. | D12: Rio Tercero | E12: Cordoba | F12: Inactiva | G12: 3600 | I12: General Lagos | J12: =SUMIF(D$4:D$152,I12,F$4:F$152) -> 18500 | K12: =J12/J$28 -> 0.002398168 | N12: Total | O12: =SUM(O4:O11) -> 7711722 | P12: =SUM(P4:P11) -> 1
B13: ÁCIDO ACRÍLICO Y SUS ÉSTERES | I13: Junin | J13: =SUMIF(D$4:D$152,I13,F$4:F$152) -> 1400 | K13: =J13/J$28 -> 0.00018148298
B14: ÁCIDO ADÍPICO | I14: Lujan de Cuyo | J14: =SUMIF(D$4:D$152,I14,F$4:F$152) -> 178000 | K14: =J14/J$28 -> 0.023074265 | N14: Capacidad instalada Provincia de Buenos Aires
B15: ÁCIDO BENZOICO | C15: PETROQUIMICA ARGENTINA S.A. | D15: San Miguel del Monte | E15: Bs As | F15: 2500 | I15: Munro | J15: =SUMIF(D$4:D$152,I15,F$4:F$152) -> 0 | K15: =J15/J$28 -> 0 | N15: Ciudad | O15: Capacidad instalada | P15: % del total
B16: ÁCIDO CÍTRICO | I16: Olmos | J16: =SUMIF(D$4:D$152,I16,F$4:F$152) -> 0 | K16: =J16/J$28 -> 0 | N16: Bahia Blanca | O16: =SUMIF(D$4:D$152,N16,F$4:F$152) -> 4302000 | P16: =O16/O$29 -> 0.73097478
B17: ÁCIDO FÓRMICO | I17: P. Huincul | J17: =SUMIF(D$4:D$152,I17,F$4:F$152) -> 411000 | K17: =J17/J$28 -> 0.053278218 | N17: Baradero | O17: =SUMIF(D$4:D$152,N17,F$4:F$152) -> 0 | P17: =O17/O$29 -> 0
B18: ÁCIDO FUMÁRICO | I18: Puerto Galvan | J18: =SUMIF(D$4:D$152,I18,F$4:F$152) -> 0 | K18: =J18/J$28 -> 0 | N18: Berazategui | O18: =SUMIF(D$4:D$152,N18,F$4:F$152) -> 0 | P18: =O18/O$29 -> 0
B19: ÁCIDO NÍTRICO | C19: AUSTIN POWDER ARGENTINA S.A. | D19: El Galpon | E19: Salta | F19: 60000 | I19: San Miguel del Monte | J19: =SUMIF(D$4:D$152,I19,F$4:F$152) -> 2500 | K19: =J19/J$28 -> 0.00032407675 | N19: Burzaco | O19: =SUMIF(D$4:D$152,N19,F$4:F$152) -> 0 | P19: =O19/O$29 -> 0
B20: ÁCIDO NÍTRICO | C20: FÁBRICA MILITAR RÍO TERCERO | D20: Rio Tercero | E20: Cordoba | F20: 39000 | I20: San Nicolas | J20: =SUMIF(D$4:D$152,I20,F$4:F$152) -> 15192 | K20: =J20/J$28 -> 0.0019693496 | N20: Campana | O20: =SUMIF(D$4:D$152,N20,F$4:F$152) -> 246700 | P20: =O20/O$29 -> 0.041918056
B21: ÁCIDO NÍTRICO | C21: FRÍO INDUSTRIAS ARGENTINAS S.A. | D21: Villa Mercedes | E21: San Luis | F21: 10730 | I21: Puerto General San Martin | J21: =SUMIF(D$4:D$152,I21,F$4:F$152) -> 819900 | K21: =J21/J$28 -> 0.10628421 | N21: Ensenada | O21: =SUMIF(D$4:D$152,N21,F$4:F$152) -> 1042500 | P21: =O21/O$29 -> 0.1771365
B22: ÁCIDO OXÁLICO | I22: Rio Tercero | J22: =SUMIF(D$4:D$152,I22,F$4:F$152) -> 74800 | K22: =J22/J$28 -> 0.0096963764 | N22: Junin | O22: =SUMIF(D$4:D$152,N22,F$4:F$152) -> 1400 | P22: =O22/O$29 -> 0.00023788115
B23: ÁCIDO SALICÍLICO | I23: San Lorenzo | J23: =SUMIF(D$4:D$152,I23,F$4:F$152) -> 34500 | K23: =J23/J$28 -> 0.0044722592 | N23: Munro | O23: =SUMIF(D$4:D$152,N23,F$4:F$152) -> 0 | P23: =O23/O$29 -> 0
B24: ÁCIDO TEREFTÁLICO | I24: San Luis | J24: =SUMIF(D$4:D$152,I24,F$4:F$152) -> 15000 | K24: =J24/J$28 -> 0.0019444605 | N24: Olmos | O24: =SUMIF(D$4:D$152,N24,F$4:F$152) -> 0 | P24: =O24/O$29 -> 0
B25: ACRILONITRILO | I25: San Miguel del Monte | J25: =SUMIF(D$4:D$152,I25,F$4:F$152) -> 2500 | K25: =J25/J$28 -> 0.00032407675 | N25: Puerto Galvan | O25: =SUMIF(D$4:D$152,N25,F$4:F$152) -> 0 | P25: =O25/O$29 -> 0
B26: ALCOHOL POLIVINÍLICO | I26: Villa Mercedes | J26: =SUMIF(D$4:D$152,I26,F$4:F$152) -> 10730 | K26: =J26/J$28 -> 0.0013909374 | N26: San Miguel del Monte | O26: =SUMIF(D$4:D$152,N26,F$4:F$152) -> 2500 | P26: =O26/O$29 -> 0.00042478776
B27: ALCOHOLES C7 a C13 | C27: YPF S.A. | D27: Ensenada | E27: Bs As | F27: 35000 | I27: Zarate | J27: =SUMIF(D$4:D$152,I27,F$4:F$152) -> 275000 | K27: =J27/J$28 -> 0.035648443 | N27: San Nicolas | O27: =SUMIF(D$4:D$152,N27,F$4:F$152) -> 15192 | P27: =O27/O$29 -> 0.0025813503
B28: ALQUILBENCENO LINEAL | C28: YPF S.A. | D28: Ensenada | E28: Bs As | F28: 53000 | I28: Total | J28: =SUM(J4:J27) -> 7714222 | K28: =SUM(K4:K27) -> 1 | N28: Zarate | O28: =SUMIF(D$4:D$152,N28,F$4:F$152) -> 275000 | P28: =O28/O$29 -> 0.046726653
B29: AMONÍACO | C29: PROFERTIL S.A. | D29: Bahia Blanca | E29: Bs As | F29: 790000 | N29: Total | O29: =SUM(O16:O28) -> 5885292 | P29: =SUM(P16:P28) -> 1
B30: AMONÍACO | C30: BUNGE ARGENTINA S.A. | D30: Campana | E30: Bs As | F30: 29700
B31: AMONÍACO | C31: AUSTIN POWDER ARGENTINA S.A. | D31: El Galpon | E31: Salta | F31: 60000
B32: ANHÍDRIDO ACÉTICO | C32: ATANOR S.C.A. | D32: Baradero | E32: Bs As | F32: Cerro | G32: 2500 | I32: Clasificacion de los productos petroquimicos
B33: ANHÍDRIDO FTÁLICO | C33: VARTECO QUÍMICA PUNTANA S.A. | D33: San Lorenzo | E33: Santa Fe | F33: 17500 | I33: Basicos | J33: Intermedios | K33: Finales
B34: ANHÍDRIDO MALEICO | C34: YPF S.A. | D34: Ensenada | E34: Bs As | F34: 17500 | I34: Amoníaco | J34: Acetaldehído | K34: ABS
B35: BENCENO | C35: YPF S.A. | D35: Ensenada | E35: Bs As | I35: Benceno | J35: Acetato de vinilo | K35: Acetato de n-butilo
B36: BENCENO | C36: PAMPA ENERGÍA S.A. | D36: Puerto General San Martin | E36: Santa Fe | I36: Butadieno | J36: Acetona | K36: Acetato de etilo
B37: BISFENOL A | I37: Buteno-1 | J37: Ácido acético | K37: Caucho acrilonitrilo-butadieno
B38: BUTADIENO | I38: Butileno | J38: Ácido adípico | K38: Caucho butilo
B39: BUTANOL SECUNDARIO | C39: CARBOCLOR S.A. | D39: Campana | E39: Bs As | F39: Inactiva | G39: 13000 | I39: Etileno | J39: Ácido benzoico | K39: Caucho estireno-butadieno
B40: BUTENO-1 | C40: YPF S.A. | D40: Ensenada | E40: Bs As | F40: 25000 | I40: Metanol | J40: Ácido fórmico | K40: Caucho etileno-propileno
B41: BUTIL HIDROXI TOLUENO - BHT | I41: Propileno | J41: Ácido fumárico | K41: Caucho polibutadieno
...

Sheet Produccion local vs nacional
Q1: Grafico 2
C3: Produccion nacional 2015 - 2024 | L3: Produccion nacional vs local 2015 2024
C4: Año | D4: T basicos | E4: % Basicos | F4: T inter | G4: % Intermedios | H4: T finales | I4: % Finales | J4: Total | L4: Año | M4: Produccion local | N4: Produccion nacional
C5: 2015 | D5: 2435900 | E5: 42 | F5: 809000 | G5: 13.9 | H5: 2559800 | I5: 44.1 | J5: 5804700 | L5: 2015 | M5: 3.424293 | N5: 5.8047
C6: 2016 | D6: 2606500 | E6: 41.8 | F6: 819600 | G6: 13.2 | H6: 2799000 | I6: 45 | J6: 6225100 | L6: 2016 | M6: 3.931271 | N6: 6.2251
C7: 2017 | D7: 2546700 | E7: 39.9 | F7: 749100 | G7: 11.7 | H7: 3092800 | I7: 48.4 | J7: 6388600 | L7: 2017 | M7: 4.236176 | N7: 6.3886
C8: 2018 | D8: 2366500 | E8: 41.8 | F8: 692100 | G8: 12.2 | H8: 2602200 | I8: 46 | J8: 5660800 | L8: 2018 | M8: 3.522561 | N8: 5.6608
C9: 2019 | D9: 2238100 | E9: 41.7 | F9: 613200 | G9: 11.4 | H9: 2521800 | I9: 46.9 | J9: 5373100 | L9: 2019 | M9: 3.425754 | N9: 5.3731
C10: 2020 | D10: 2176600 | E10: 39.7 | F10: 588500 | G10: 10.7 | H10: 2718700 | I10: 49.6 | J10: 5483800 | L10: 2020 | M10: 3.912917 | N10: 5.4838
C11: 2021 | D11: 2161200 | E11: 40.9 | F11: 679700 | G11: 12.8 | H11: 2447200 | I11: 46.3 | J11: 5288100 | L11: 2021 | M11: 3.22912 | N11: 5.2881
C12: 2022 | D12: 2566300 | E12: 40.3 | F12: 740600 | G12: 11.6 | H12: 3060600 | I12: 48.1 | J12: 6367500 | L12: 2022 | M12: 4.183785 | N12: 6.3675
C13: 2023 | D13: 2454900 | E13: 40.3 | F13: 701100 | G13: 11.5 | H13: 2940100 | I13: 48.2 | J13: 6096100 | L13: 2023 | M13: 3.994434 | N13: 6.0961
C14: 2024 | D14: 2485000 | E14: 41.9 | F14: 642700 | G14: 10.8 | H14: 2808900 | I14: 47.3 | J14: 5936600 | L14: 2024 | M14: 3.999692 | N14: 5.9366
C17: Produccion Bahia Blanca 2024 | L17: Producto | M17: 2015 | N17: 2016 | O17: 2017 | P17: 2018 | Q17: 2019 | R17: 2020 | S17: 2021 | T17: 2022 | U17: 2023 | V17: 2024
C18: Producto Petroquimico | D18: Planta | E18: Ciudad | F18: Provincia | G18: Capacidad instalada | H18: U$S/t | I18: Produccion local | J18: Valoracion de la produccion | L18: AMONÍACO | M18: 608529 | N18: 740893 | O18: 856961 | P18: 627093 | Q18: 729766 | R18: 778003 | S18: 593433 | T18: 886236 | U18: 777865 | V18: 853645
C19: AMONÍACO | D19: PROFERTIL S.A. | E19: Bahia Blanca | F19: Bs As | G19: 790000 | H19: 323 | I19: 853645 | J19: ='Produccion local vs nacional'!$H19*'Produccion local vs nacional'!$I19 -> 275727335 | L19: CLORURO DE VINILO | M19: 202977 | N19: 214188 | O19: 186961 | P19: 185666 | Q19: 160919 | R19: 169410 | S19: 188015 | T19: 201954 | U19: 194769 | V19: 183857
C20: CLORURO DE VINILO | D20: UNIPAR INDUPA S.A.I.C. | E20: Bahia Blanca | F20: Bs As | G20: 231000 | H20: 550 | I20: 183857 | J20: ='Produccion local vs nacional'!$H20*'Produccion local vs nacional'!$I20 -> 101121350 | L20: DICLOROETILENO | M20: 176001 | N20: 186723 | O20: 161280 | P20: 161788 | Q20: 141568 | R20: 132240 | S20: 144372 | T20: 170017 | U20: 164124 | V20: 160508
C21: DICLOROETILENO | D21: UNIPAR INDUPA S.A.I.C. | E21: Bahia Blanca | F21: Bs As | G21: 266000 | H21: 149 | I21: 160508 | J21: ='Produccion local vs nacional'!$H21*'Produccion local vs nacional'!$I21 -> 23915692 | L21: ETILENO | M21: 718038 | N21: 771232 | O21: 726352 | P21: 718057 | Q21: 546109 | R21: 736784 | S21: 649076 | T21: 707675 | U21: 761850 | V21: 667918
C22: ETILENO | D22: PBBPolisur S.R.L. | E22: Bahia Blanca | F22: Bs As | G22: 750000 | H22: 946 | I22: 667918 | J22: ='Produccion local vs nacional'!$H22*'Produccion local vs nacional'!$I22 -> 631850428 | L22: POLICLORURO DE VINILO (PVC) Y COPOLÍMEROS | M22: 204045 | N22: 212579 | O22: 187361 | P22: 184077 | Q22: 161511 | R22: 168628 | S22: 185740 | T22: 203440 | U22: 194865 | V22: 182556
C23: ETILENO | D23: PBBPolisur S.R.L. | E23: Bahia Blanca | F23: Bs As | J23: ='Produccion local vs nacional'!$H23*'Produccion local vs nacional'!$I23 -> 0 | L23: POLIETILENO DE ALTA DENSIDAD | M23: 249443 | N23: 286920 | O23: 258638 | P23: 304276 | Q23: 211794 | R23: 283294 | S23: 250126 | T23: 276054 | U23: 283406 | V23: 250701
C24: POLICLORURO DE VINILO (PVC) Y COPOLÍMEROS | D24: UniPAR INDUPA S.A.I.C. | E24: Bahia Blanca | F24: Bs As | G24: 230000 | H24: 1218 | I24: 182556 | J24: ='Produccion local vs nacional'!$H24*'Produccion local vs nacional'!$I24 -> 222353208 | L24: POLIETILENO DE BAJA DENSIDAD CONVENCIONAL | M24: 72728 | N24: 3114 | O24: 84051 | P24: 90363 | Q24: 78428 | R24: 99758 | S24: 80509 | T24: 88874 | U24: 95641 | V24: 93802
C25: POLIETILENO DE ALTA DENSIDAD | D25: PBBPolisur S.R.L. | E25: Bahia Blanca | F25: Bs As | G25: 135000 | I25: 250701 | J25: ='Produccion local vs nacional'!$H25*'Produccion local vs nacional'!$I25 -> 0 | L25: POLIETILENO DE BAJA DENSIDAD LINEAL | M25: 260302 | N25: 309886 | O25: 279610 | P25: 235234 | Q25: 217261 | R25: 261225 | S25: 219141 | T25: 271714 | U25: 301835 | V25: 274288
C26: POLIETILENO DE ALTA DENSIDAD | D26: PBBPolisur S.R.L. | E26: Bahia Blanca | F26: Bs As | J26: ='Produccion local vs nacional'!$H26*'Produccion local vs nacional'!$I26 -> 0 | L26: UREA | M26: 932230 | N26: 1205736 | O26: 1494962 | P26: 1016007 | Q26: 1178398 | R26: 1283575 | S26: 918708 | T26: 1377821 | U26: 1220079 | V26: 1332417
C27: POLIETILENO DE ALTA DENSIDAD | D27: PBBPolisur S.R.L. | E27: Bahia Blanca | F27: Bs As | J27: ='Produccion local vs nacional'!$H27*'Produccion local vs nacional'!$I27 -> 0 | L27: Total | M27: =SUM(M18:M26) -> 3424293 | N27: =SUM(N18:N26) -> 3931271 | O27: =SUM(O18:O26) -> 4236176 | P27: =SUM(P18:P26) -> 3522561 | Q27: =SUM(Q18:Q26) -> 3425754 | R27: =SUM(R18:R26) -> 3912917 | S27: =SUM(S18:S26) -> 3229120 | T27: =SUM(T18:T26) -> 4183785 | ... V27: =SUM(V18:V26) -> 3999692
C28: POLIETILENO DE BAJA DENSIDAD CONVENCIONAL | D28: PBBPolisur S.R.L. | E28: Bahia Blanca | F28: Bs As | G28: 110000 | H28: 1312 | I28: 93802 | J28: ='Produccion local vs nacional'!$H28*'Produccion local vs nacional'!$I28 -> 123068224
C29: POLIETILENO DE BAJA DENSIDAD LINEAL | D29: PBBPolisur S.R.L. | E29: Bahia Blanca | F29: Bs As | G29: 520000 | I29: 274288 | J29: ='Produccion local vs nacional'!$H29*'Produccion local vs nacional'!$I29 -> 0
C30: POLIETILENO DE BAJA DENSIDAD LINEAL | D30: PBBPolisur S.R.L. | E30: Bahia Blanca | F30: Bs As | J30: ='Produccion local vs nacional'!$H30*'Produccion local vs nacional'!$I30 -> 0
C31: UREA | D31: PROFERTIL S.A. | E31: Bahia Blanca | F31: Bs As | G31: 1320000 | H31: 378 | I31: 1332417 | J31: ='Produccion local vs nacional'!$H31*'Produccion local vs nacional'!$I31 -> 503653626
C32: Total | G32: =SUM(G19:G31) -> 4352000 | I32: =SUM(I19:I31) -> 3999692 | J32: =SUM(J19:J31) -> 1881689863
C34: Consumo aparente local | I34: 2024
C35: 2021 | I35: Producto Petroquimico | J35: Planta | K35: Ciudad | L35: Provincia | M35: Consumo aparente local | N35: CIF | O35: FOB | P35: VALOR CIF | Q35: VALOR FOB | R35: Valuacion
C36: Producto Petroquimico | D36: Planta | E36: Ciudad | F36: Provincia | G36: Consumo aparente local | I36: AMONÍACO | J36: PROFERTIL S.A. | K36: Bahia Blanca | L36: Bs As | M36: 821676 | O36: 323 | P36: =N36*M36 -> 0 | Q36: =O36*M36 -> 265401348 | R36: 265401348
C37: AMONÍACO | D37: PROFERTIL S.A. | E37: Bahia Blanca | F37: Bs As | G37: 566856 | I37: CLORURO DE VINILO | J37: UNIPAR INDUPA S.A.I.C. | K37: Bahia Blanca | L37: Bs As | M37: 183857 | P37: =N37*M37 -> 0 | Q37: =O37*M37 -> 0 | R37: 0
C38: CLORURO DE VINILO | D38: UNIPAR INDUPA S.A.I.C. | E38: Bahia Blanca | F38: Bs As | G38: 188015 | I38: DICLOROETILENO | J38: UNIPAR INDUPA S.A.I.C. | K38: Bahia Blanca | L38: Bs As | M38: 160508 | P38: =N38*M38 -> 0 | Q38: =O38*M38 -> 0
C39: DICLOROETILENO | D39: UNIPAR INDUPA S.A.I.C. | E39: Bahia Blanca | F39: Bs As | G39: 164823 | I39: ETILENO | J39: PBBPolisur S.R.L. | K39: Bahia Blanca | L39: Bs As | M39: 711218 | N39: 946 | P39: =N39*M39 -> 672812228 | Q39: =O39*M39 -> 0 | R39: 672812228
C40: ETILENO | D40: PBBPolisur S.R.L. | E40: Bahia Blanca | F40: Bs As | G40: 640928 | I40: ETILENO | J40: PBBPolisur S.R.L. | K40: Bahia Blanca | L40: Bs As | P40: =N40*M40 -> 0 | Q40: =O40*M40 -> 0 | R40: 0
C41: ETILENO | D41: PBBPolisur S.R.L. | E41: Bahia Blanca | F41: Bs As | I41: POLICLORURO DE VINILO (PVC) Y COPOLÍMEROS | J41: UniPAR INDUPA S.A.I.C. | K41: Bahia Blanca | L41: Bs As | M41: 99354 | N41: 1677 | O41: 759 | P41: =N41*M41 -> 166616658 | Q41: =O41*M41 -> 75409686 | R41: 75409686
C42: POLICLORURO DE VINILO (PVC) Y COPOLÍMEROS | D42: UniPAR INDUPA S.A.I.C. | E42: Bahia Blanca | F42: Bs As | G42: 159339 | I42: POLIETILENO DE ALTA DENSIDAD | J42: PBBPolisur S.R.L. | K42: Bahia Blanca | L42: Bs As | M42: 214373 | N42: 1489 | O42: 1202 | P42: =N42*M42 -> 319201397 | Q42: =O42*M42 -> 257676346 | R42: 257676346
C43: POLIETILENO DE ALTA DENSIDAD | D43: PBBPolisur S.R.L. | E43: Bahia Blanca | F43: Bs As | G43: 251651 | I43: POLIETILENO DE ALTA DENSIDAD | J43: PBBPolisur S.R.L. | K43: Bahia Blanca | L43: Bs As | P43: =N43*M43 -> 0 | Q43: =O43*M43 -> 0 | R43: 0
C44: POLIETILENO DE ALTA DENSIDAD | D44: PBBPolisur S.R.L. | E44: Bahia Blanca | F44: Bs As | I44: POLIETILENO DE ALTA DENSIDAD | J44: PBBPolisur S.R.L. | K44: Bahia Blanca | L44: Bs As | P44: =N44*M44 -> 0 | Q44: =O44*M44 -> 0 | R44: 0
...

Sheet Impo y Expo
D2: Importaciones | M2: Saldo comercial | T2: Valuacion importaciones y exportaciones en USD
D3: Año | E3: T basicos | F3: % Basicos | G3: T inter | H3: % Intermedios | I3: T finales | J3: % Finales | K3: Total | M3: Año | N3: T basicos | O3: T inter | P3: T finales | Q3: Total | T3: Año | U3: $ Importaciones | V3: $ Exportaciones | W3: Saldo
D4: 2015 | E4: 50400 | F4: 3 | G4: 410300 | H4: 24.2 | I4: 1237000 | J4: 72.8 | K4: 1697700 | M4: 2015 | N4: =E18-'Impo y Expo'!$E4 -> 207600 | O4: =G18-'Impo y Expo'!$G4 -> -320900 | P4: =I18-'Impo y Expo'!$I4 -> -717700 | Q4: =K18-'Impo y Expo'!$K4 -> -831000 | T4: 2021 | U4: =SUMIF(Tabla28[AÑO], "2021",Tabla28[Valuacion Impo])/1000000 -> 3849.8031 | V4: =SUMIF(Tabla28[AÑO], "2021",Tabla28[Valuacion Expo])/1000000 -> 849.62506 | W4: =V4-U4 -> -3000.178
D5: 2016 | E5: 58500 | F5: 3 | G5: 363000 | H5: 18.4 | I5: 1554000 | J5: 78.6 | K5: 1975500 | M5: 2016 | N5: =E19-'Impo y Expo'!$E5 -> 89300 | O5: =G19-'Impo y Expo'!$G5 -> -261900 | P5: =I19-'Impo y Expo'!$I5 -> -863500 | Q5: =K19-'Impo y Expo'!$K5 -> -1036100 | T5: 2022 | U5: =SUMIF(Tabla28[AÑO], "2022",Tabla28[Valuacion Impo])/1000000 -> 4660.8766 | V5: =SUMIF(Tabla28[AÑO], "2022",Tabla28[Valuacion Expo])/1000000 -> 942.03539 | W5: =V5-U5 -> -3718.8412
D6: 2017 | E6: 122500 | F6: 6.3 | G6: 371700 | H6: 19.1 | I6: 1447500 | J6: 74.6 | K6: 1941700 | M6: 2017 | N6: =E20-'Impo y Expo'!$E6 -> -66200 | O6: =G20-'Impo y Expo'!$G6 -> -292600 | P6: =I20-'Impo y Expo'!$I6 -> -841300 | Q6: =K20-'Impo y Expo'!$K6 -> -1200100 | T6: 2023 | U6: =SUMIF(Tabla28[AÑO], "2023",Tabla28[Valuacion Impo])/1000000 -> 3008.2547 | V6: =SUMIF(Tabla28[AÑO], "2023",Tabla28[Valuacion Expo])/1000000 -> 629.08204 | W6: =V6-U6 -> -2379.1727
D7: 2018 | E7: 45200 | F7: 2 | G7: 365600 | H7: 16.3 | I7: 1837600 | J7: 81.7 | K7: 2248400 | M7: 2018 | N7: =E21-'Impo y Expo'!$E7 -> 103500 | O7: =G21-'Impo y Expo'!$G7 -> -300800 | P7: =I21-'Impo y Expo'!$I7 -> -1134500 | Q7: =K21-'Impo y Expo'!$K7 -> -1331800 | T7: 2024 | U7: =SUMIF(Tabla28[AÑO], "2024",Tabla28[Valuacion Impo])/1000000 -> 2711.1955 | V7: =SUMIF(Tabla28[AÑO], "2024",Tabla28[Valuacion Expo])/1000000 -> 910.82528 | W7: =V7-U7 -> -1800.3702
D8: 2019 | E8: 97900 | F8: 4.1 | G8: 327200 | H8: 13.8 | I8: 1955100 | J8: 82.1 | K8: 2380200 | M8: 2019 | N8: =E22-'Impo y Expo'!$E8 -> 81600 | O8: =G22-'Impo y Expo'!$G8 -> -263800 | P8: =I22-'Impo y Expo'!$I8 -> -1303000 | Q8: =K22-'Impo y Expo'!$K8 -> -1485200
D9: 2020 | E9: 112200 | F9: 4.1 | G9: 334500 | H9: 12.2 | I9: 2299600 | J9: 83.7 | K9: 2746300 | M9: 2020 | N9: =E23-'Impo y Expo'!$E9 -> 25700 | O9: =G23-'Impo y Expo'!$G9 -> -298300 | P9: =I23-'Impo y Expo'!$I9 -> -1755700 | Q9: =K23-'Impo y Expo'!$K9 -> -2028300
D10: 2021 | E10: 44400 | F10: 1.3 | G10: 410900 | H10: 12.6 | I10: 2814700 | J10: 86.1 | K10: 3270000 | M10: 2021 | N10: =E24-'Impo y Expo'!$E10 -> 117000 | O10: =G24-'Impo y Expo'!$G10 -> -383100 | P10: =I24-'Impo y Expo'!$I10 -> -2322200 | Q10: =K24-'Impo y Expo'!$K10 -> -2588300
D11: 2022 | E11: 82300 | F11: 3.3 | G11: 401800 | H11: 16.3 | I11: 1990200 | J11: 80.4 | K11: 2474300 | M11: 2022 | N11: =E25-'Impo y Expo'!$E11 -> -1900 | O11: =G25-'Impo y Expo'!$G11 -> -374500 | P11: =I25-'Impo y Expo'!$I11 -> -1477900 | Q11: =K25-'Impo y Expo'!$K11 -> -1854300 | T11: Grafico 6 | AA11: Grafico 3
D12: 2023 | E12: 43400 | F12: 2 | G12: 364500 | H12: 16.4 | I12: 1811400 | J12: 81.6 | K12: 2219300 | M12: 2023 | N12: =E26-'Impo y Expo'!$E12 -> 163900 | O12: =G26-'Impo y Expo'!$G12 -> -349700 | P12: =I26-'Impo y Expo'!$I12 -> -1374800 | Q12: =K26-'Impo y Expo'!$K12 -> -1560600
D13: 2024 | E13: 72100 | F13: 3.1 | G13: 232500 | H13: 10 | I13: 2013300 | J13: 86.9 | K13: 2317900 | M13: 2024 | N13: =E27-'Impo y Expo'!$E13 -> 228600 | O13: =G27-'Impo y Expo'!$G13 -> -210200 | P13: =I27-'Impo y Expo'!$I13 -> -1395900 | Q13: =K27-'Impo y Expo'!$K13 -> -1377500
D16: Exportaciones | M16: Saldos expresados en millones de toneladas
D17: Año | E17: T basicos | F17: % Basicos | G17: T inter | H17: % Intermedios | I17: T finales | J17: % Finales | K17: Total | M17: Año | N17: Exportaciones | O17: Importaciones | P17: Saldo comercial
D18: 2015 | E18: 258000 | F18: 29.8 | G18: 89400 | H18: 10.3 | I18: 519300 | J18: 59.9 | K18: 866700 | M18: 2015 | N18: ='Impo y Expo'!$K18/1000000 -> 0.8667 | O18: =K4/1000000 -> 1.6977 | P18: =Q4/1000000 -> -0.831
D19: 2016 | E19: 147800 | F19: 15.7 | G19: 101100 | H19: 10.8 | I19: 690500 | J19: 73.5 | K19: 939400 | M19: 2016 | N19: ='Impo y Expo'!$K19/1000000 -> 0.9394 | O19: =K5/1000000 -> 1.9755 | P19: =Q5/1000000 -> -1.0361
D20: 2017 | E20: 56300 | F20: 7.6 | G20: 79100 | H20: 10.7 | I20: 606200 | J20: 81.7 | K20: 741600 | M20: 2017 | N20: ='Impo y Expo'!$K20/1000000 -> 0.7416 | O20: =K6/1000000 -> 1.9417 | P20: =Q6/1000000 -> -1.2001
D21: 2018 | E21: 148700 | F21: 16.2 | G21: 64800 | H21: 7.1 | I21: 703100 | J21: 76.7 | K21: 916600 | M21: 2018 | N21: ='Impo y Expo'!$K21/1000000 -> 0.9166 | O21: =K7/1000000 -> 2.2484 | P21: =Q7/1000000 -> -1.3318
D22: 2019 | E22: 179500 | F22: 20 | G22: 63400 | H22: 7.1 | I22: 652100 | J22: 72.9 | K22: 895000 | M22: 2019 | N22: ='Impo y Expo'!$K22/1000000 -> 0.895 | O22: =K8/1000000 -> 2.3802 | P22: =Q8/1000000 -> -1.4852
D23: 2020 | E23: 137900 | F23: 19.2 | G23: 36200 | H23: 5 | I23: 543900 | J23: 75.8 | K23: 718000 | M23: 2020 | N23: ='Impo y Expo'!$K23/1000000 -> 0.718 | O23: =K9/1000000 -> 2.7463 | P23: =Q9/1000000 -> -2.0283
D24: 2021 | E24: 161400 | F24: 23.7 | G24: 27800 | H24: 4.1 | I24: 492500 | J24: 72.2 | K24: 681700 | M24: 2021 | N24: ='Impo y Expo'!$K24/1000000 -> 0.6817 | O24: =K10/1000000 -> 3.27 | P24: =Q10/1000000 -> -2.5883
D25: 2022 | E25: 80400 | F25: 13 | G25: 27300 | H25: 4.4 | I25: 512300 | J25: 82.6 | K25: 620000 | M25: 2022 | N25: ='Impo y Expo'!$K25/1000000 -> 0.62 | O25: =K11/1000000 -> 2.4743 | P25: =Q11/1000000 -> -1.8543
D26: 2023 | E26: 207300 | F26: 31.5 | G26: 14800 | H26: 2.2 | I26: 436600 | J26: 66.3 | K26: 658700 | M26: 2023 | N26: ='Impo y Expo'!$K26/1000000 -> 0.6587 | O26: =K12/1000000 -> 2.2193 | P26: =Q12/1000000 -> -1.5606
D27: 2024 | E27: 300700 | F27: 32 | G27: 22300 | H27: 2.4 | I27: 617400 | J27: 65.6 | K27: 940400 | M27: 2024 | N27: ='Impo y Expo'!$K27/1000000 -> 0.9404 | O27: =K13/1000000 -> 2.3179 | P27: =Q13/1000000 -> -1.3775
N30: Impo y expo valuacion 2024 | W30: Producto | X30: AÑO | Y30: IMPO. (t) | Z30: EXPO. (t) | AA30: IMPO. (US$/t) | AB30: EXPO. (US$/t) | AC30: Valuacion Impo | AD30: Valuacion Expo
D31: Exportaciones a nivel local | I31: Importaciones a nivel local | N31: Producto Petroquimico | O31: Tipo de producto | P31: Exportaciones | Q31: Importaciones | R31: FOB | S31: CIF | T31: Valor FOB | U31: Valor CIF | W31: ABS | X31: 2021 | Y31: 10785 | Z31: 8 | AA31: 2835 | AC31: =Y31*AA31 -> 30575475 | AD31: =Z31*AB31 -> 0
D32: Producto | E32: Volumen exportado en t | F32: FOB | G32: Valuacion | I32: Producto | J32: Volumen exportado en t | K32: CIF | L32: Valuacion | N32: ABS | O32: Final | Q32: 5166 | S32: 2606 | T32: =P32*R32 -> 0 | U32: =Q32*S32 -> 13462596 | W32: ABS | X32: 2022 | Y32: 10025 | AA32: 3074 | AC32: =Y32*AA32 -> 30816850 | AD32: =Z32*AB32 -> 0
D33: AMONÍACO | E33: 31970 | F33: 323 | G33: ='Impo y Expo'!$E33*'Impo y Expo'!$F33 -> 10326310 | I33: AMONÍACO | J33: 0 | L33: ='Impo y Expo'!$J33*'Impo y Expo'!$K33 -> 0 | N33: ACETALDEHÍDO | O33: Intermedio | T33: =P33*R33 -> 0 | U33: =Q33*S33 -> 0 | W33: ABS | X33: 2023 | Y33: 9147 | AA33: 2510 | AC33: =Y33*AA33 -> 22958970 | AD33: =Z33*AB33 -> 0
D34: CLORURO DE VINILO | E34: 0 | G34: ='Impo y Expo'!$E34*'Impo y Expo'!$F34 -> 0 | I34: CLORURO DE VINILO | J34: 0 | L34: ='Impo y Expo'!$J34*'Impo y Expo'!$K34 -> 0 | N34: ACETATO DE n-BUTILO | O34: Final | Q34: 2072 | S34: 1541 | T34: =P34*R34 -> 0 | U34: =Q34*S34 -> 3192952 | W34: ABS | X34: 2024 | Y34: 5166 | Z34: 2 | AA34: 2606 | AC34: =Y34*AA34 -> 13462596 | AD34: =Z34*AB34 -> 0
D35: DICLOROETILENO | E35: 0 | G35: ='Impo y Expo'!$E35*'Impo y Expo'!$F35 -> 0 | I35: DICLOROETILENO | J35: 0 | L35: ='Impo y Expo'!$J35*'Impo y Expo'!$K35 -> 0 | N35: ACETATO DE ETILO | O35: Final | Q35: 10682 | S35: 1243 | T35: =P35*R35 -> 0 | U35: =Q35*S35 -> 13277726 | W35: Acetaldehído | X35: 2021 | AC35: =Y35*AA35 -> 0 | AD35: =Z35*AB35 -> 0
D36: ETILENO | E36: 0 | G36: ='Impo y Expo'!$E36*'Impo y Expo'!$F36 -> 0 | I36: ETILENO | J36: 43300 | K36: 946 | L36: ='Impo y Expo'!$J36*'Impo y Expo'!$K36 -> 40961800 | N36: ACETATO DE VINILO | O36: Intermedio | Q36: 3336 | S36: 1354 | T36: =P36*R36 -> 0 | U36: =Q36*S36 -> 4516944 | W36: Acetaldehído | X36: 2022 | AC36: =Y36*AA36 -> 0 | AD36: =Z36*AB36 -> 0
D37: POLICLORURO DE VINILO (PVC) Y COPOLÍMEROS | E37: 93187 | F37: 759 | G37: ='Impo y Expo'!$E37*'Impo y Expo'!$F37 -> 70728933 | I37: POLICLORURO DE VINILO (PVC) Y COPOLÍMEROS | J37: 9985 | K37: 1677 | L37: ='Impo y Expo'!$J37*'Impo y Expo'!$K37 -> 16744845 | N37: ACETONA | O37: Intermedio | Q37: 3346 | S37: 1514 | T37: =P37*R37 -> 0 | U37: =Q37*S37 -> 5065844 | W37: Acetaldehído | X37: 2023 | Y37: 1 | AC37: =Y37*AA37 -> 0 | AD37: =Z37*AB37 -> 0
D38: POLIETILENO DE ALTA DENSIDAD | E38: 125319 | F38: 1202 | G38: ='Impo y Expo'!$E38*'Impo y Expo'!$F38 -> 150633438 | I38: POLIETILENO DE ALTA DENSIDAD | J38: 88991 | K38: 1489 | L38: ='Impo y Expo'!$J38*'Impo y Expo'!$K38 -> 132507599 | N38: Ácido acético | O38: Intermedio | T38: =P38*R38 -> 0 | U38: =Q38*S38 -> 0 | W38: Acetaldehído | X38: 2024 | Y38: 5 | AC38: =Y38*AA38 -> 0 | AD38: =Z38*AB38 -> 0
D39: POLIETILENO DE BAJA DENSIDAD CONVENCIONAL | E39: 27511 | F39: 1185 | G39: ='Impo y Expo'!$E39*'Impo y Expo'!$F39 -> 32600535 | I39: POLIETILENO DE BAJA DENSIDAD CONVENCIONAL | J39: 125823 | K39: 1439 | L39: ='Impo y Expo'!$J39*'Impo y Expo'!$K39 -> 181059297 | N39: Ácido acético | O39: Intermedio | P39: 232 | Q39: 5664 | R39: 1964 | S39: 900 | T39: =P39*R39 -> 455648 | U39: =Q39*S39 -> 5097600 | W39: Acetato de n-Butilo | X39: 2021 | Y39: 2924 | AA39: 1885 | AC39: =Y39*AA39 -> 5511740 | AD39: =Z39*AB39 -> 0
D40: POLIETILENO DE BAJA DENSIDAD LINEAL | E40: 122909 | F40: 1140 | G40: ='Impo y Expo'!$E40*'Impo y Expo'!$F40 -> 140116260 | I40: POLIETILENO DE BAJA DENSIDAD LINEAL | J40: 67134 | K40: 1508 | L40: ='Impo y Expo'!$J40*'Impo y Expo'!$K40 -> 101238072 | N40: ÁCIDO ACRÍLICO Y SUS ÉSTERES | O40: Intermedio | Q40: 14125 | S40: 1626 | T40: =P40*R40 -> 0 | U40: =Q40*S40 -> 22967250 | W40: Acetato de n-Butilo | X40: 2022 | Y40: 2199 | AA40: 1982 | AC40: =Y40*AA40 -> 4358418 | AD40: =Z40*AB40 -> 0
D41: UREA | E41: 0 | G41: ='Impo y Expo'!$E41*'Impo y Expo'!$F41 -> 0 | I41: UREA | J41: 1081189 | K41: 378 | L41: ='Impo y Expo'!$J41*'Impo y Expo'!$K41 -> 408689442 | N41: ÁCIDO ADÍPICO | O41: Intermedio | Q41: 1485 | S41: 1523 | T41: =P41*R41 -> 0 | U41: =Q41*S41 -> 2261655 | W41: Acetato de n-Butilo | X41: 2023 | Y41: 2416 | AA41: 1502 | AC41: =Y41*AA41 -> 3628832 | AD41: =Z41*AB41 -> 0
D42: Total | E42: =SUM(E33:E41) -> 400896 | G42: =SUM(G33:G41) -> 404405476 | I42: Total | J42: =SUM(J33:J41) -> 1416422 | L42: =SUM(L33:L41) -> 881201055 | N42: ÁCIDO BENZOICO | O42: Intermedio | Q42: 202 | S42: 1770 | T42: =P42*R42 -> 0 | U42: =Q42*S42 -> 357540 | W42: Acetato de n-Butilo | X42: 2024 | Y42: 2072 | AA42: 1541 | AC42: =Y42*AA42 -> 3192952 | AD42: =Z42*AB42 -> 0
N43: ÁCIDO CÍTRICO | O43: No encontrado | P43: 171 | Q43: 24552 | R43: 3243 | S43: 1294 | T43: =P43*R43 -> 554553 | U43: =Q43*S43 -> 31770288 | W43: Acetato de Etilo | X43: 2021 | Y43: 13730 | Z43: 368 | AA43: 1089 | AC43: =Y43*AA43 -> 14951970 | AD43: =Z43*AB43 -> 0
N44: ÁCIDO 2-ETILHEXANOICO | O44: No encontrado | Q44: 593 | S44: 2426 | T44: =P44*R44 -> 0 | U44: =Q44*S44 -> 1438618 | W44: Acetato de Etilo | X44: 2022 | Y44: 12014 | Z44: 234 | AA44: 1358 | AC44: =Y44*AA44 -> 16315012 | AD44: =Z44*AB44 -> 0
N45: ÁCIDO FÓRMICO | O45: Intermedio | Q45: 6771 | S45: 716 | T45: =P45*R45 -> 0 | U45: =Q45*S45 -> 4848036 | W45: Acetato de Etilo | X45: 2023 | Y45: 13700 | AA45: 1302 | AC45: =Y45*AA45 -> 17837400 | AD45: =Z45*AB45 -> 0
...

Sheet Consumo aparente nacional
D3: Año | E3: T basicos | F3: % Basicos | G3: T inter | H3: % Intermedios | I3: T finales | J3: % Finales | K3: Total
D4: 2015 | E4: 2228300 | F4: 33.6 | G4: 1129900 | H4: 17 | I4: 3277500 | J4: 49.4 | K4: 6635700
D5: 2016 | E5: 2517200 | F5: 35.2 | G5: 1081500 | H5: 17 | I5: 3662500 | J5: 47.8 | K5: 7261200
D6: 2017 | E6: 2612900 | F6: 34.4 | G6: 1041700 | H6: 13.7 | I6: 3934100 | J6: 51.9 | K6: 7588700
D7: 2018 | E7: 2263000 | F7: 32.4 | G7: 992900 | H7: 14.2 | I7: 3736700 | J7: 53.4 | K7: 6992600
D8: 2019 | E8: 2156500 | F8: 31.4 | G8: 877000 | H8: 12.8 | I8: 3824800 | J8: 55.8 | K8: 6858300
D9: 2020 | E9: 2150900 | F9: 28.6 | G9: 886800 | H9: 11.8 | I9: 4474400 | J9: 59.6 | K9: 7512100
D10: 2021 | E10: 2044200 | F10: 26 | G10: 1062800 | H10: 13.5 | I10: 4769400 | J10: 60.5 | K10: 7876400
D11: 2022 | E11: 2568200 | F11: 31.2 | G11: 1115100 | H11: 13.6 | I11: 4538500 | J11: 55.2 | K11: 8221800
D12: 2023 | E12: 2291000 | F12: 29.9 | G12: 1050800 | H12: 13.7 | I12: 4314900 | J12: 56.4 | K12: 7656700
D13: 2024 | E13: 2256400 | F13: 30.8 | G13: 852900 | H13: 11.7 | I13: 4204800 | J13: 57.5 | K13: 7314100
D15: Consumo aparente expresada en millones de dolares | J15: Grafico 5
D16: Año | E16: Basicos | F16: Intermedios | G16: Finales | H16: Total
D17: 2015 | E17: =E4/1000000 -> 2.2283 | F17: =G4/1000000 -> 1.1299 | G17: =I4/1000000 -> 3.2775 | H17: =K4/1000000 -> 6.6357
D18: 2016 | E18: =E5/1000000 -> 2.5172 | F18: =G5/1000000 -> 1.0815 | G18: =I5/1000000 -> 3.6625 | H18: =K5/1000000 -> 7.2612
D19: 2017 | E19: =E6/1000000 -> 2.6129 | F19: =G6/1000000 -> 1.0417 | G19: =I6/1000000 -> 3.9341 | H19: =K6/1000000 -> 7.5887
D20: 2018 | E20: =E7/1000000 -> 2.263 | F20: =G7/1000000 -> 0.9929 | G20: =I7/1000000 -> 3.7367 | H20: =K7/1000000 -> 6.9926
D21: 2019 | E21: =E8/1000000 -> 2.1565 | F21: =G8/1000000 -> 0.877 | G21: =I8/1000000 -> 3.8248 | H21: =K8/1000000 -> 6.8583
D22: 2020 | E22: =E9/1000000 -> 2.1509 | F22: =G9/1000000 -> 0.8868 | G22: =I9/1000000 -> 4.4744 | H22: =K9/1000000 -> 7.5121
D23: 2021 | E23: =E10/1000000 -> 2.0442 | F23: =G10/1000000 -> 1.0628 | G23: =I10/1000000 -> 4.7694 | H23: =K10/1000000 -> 7.8764
D24: 2022 | E24: =E11/1000000 -> 2.5682 | F24: =G11/1000000 -> 1.1151 | G24: =I11/1000000 -> 4.5385 | H24: =K11/1000000 -> 8.2218
D25: 2023 | E25: =E12/1000000 -> 2.291 | F25: =G12/1000000 -> 1.0508 | G25: =I12/1000000 -> 4.3149 | H25: =K12/1000000 -> 7.6567
D26: 2024 | E26: =E13/1000000 -> 2.2564 | F26: =G13/1000000 -> 0.8529 | G26: =I13/1000000 -> 4.2048 | H26: =K13/1000000 -> 7.3141

Sheet Materias primas
C4: Materias primas petroquimicas
C5: Materias primas | D5: 2020 | E5: 2021 | F5: 2022 | G5: 2023 | H5: 2024
C6: Etano | D6: 937859 | E6: 836605 | F6: 913454 | G6: 973919 | H6: 844400
C7: Propano | D7: 1364953 | E7: 1399535 | F7: 1474883 | G7: 1515449 | H7: 1518875 | N7: Grafico 4
C8: Butano | D8: 1051251 | E8: 1036711 | F8: 1195699 | G8: 1317180 | H8: 1376525
C9: Nafta | D9: 1547818 | E9: 1738142 | F9: 1815707 | G9: 1615160 | H9: 1682322
C10: Total | D10: =SUM(D6:D9) -> 4901881 | E10: =SUM(E6:E9) -> 5010993 | F10: =SUM(F6:F9) -> 5399743 | G10: =SUM(G6:G9) -> 5421708 | H10: =SUM(H6:H9) -> 5422122
C13: Materias primas petroquimicas en millones de t
C14: Materias primas | D14: 2020 | E14: 2021 | F14: 2022 | G14: 2023 | H14: 2024
C15: Etano | D15: =D6/1000000 -> 0.937859 | E15: =E6/1000000 -> 0.836605 | F15: =F6/1000000 -> 0.913454 | G15: =G6/1000000 -> 0.973919 | H15: =H6/1000000 -> 0.8444
C16: Propano | D16: =D7/1000000 -> 1.364953 | E16: =E7/1000000 -> 1.399535 | F16: =F7/1000000 -> 1.474883 | G16: =G7/1000000 -> 1.515449 | H16: =H7/1000000 -> 1.518875
C17: Butano | D17: =D8/1000000 -> 1.051251 | E17: =E8/1000000 -> 1.036711 | F17: =F8/1000000 -> 1.195699 | G17: =G8/1000000 -> 1.31718 | H17: =H8/1000000 -> 1.376525
C18: Nafta | D18: =D9/1000000 -> 1.547818 | E18: =E9/1000000 -> 1.738142 | F18: =F9/1000000 -> 1.815707 | G18: =G9/1000000 -> 1.61516 | H18: =H9/1000000 -> 1.682322
C19: Total | D19: =D10/1000000 -> 4.901881 | E19: =E10/1000000 -> 5.010993 | F19: =F10/1000000 -> 5.399743 | G19: =G10/1000000 -> 5.421708 | H19: =H10/1000000 -> 5.422122

Sheet Clasificacion de bienes
D3: Basicos | E3: Intermedios | F3: Finales
D4: Amoníaco | E4: Acetaldehído | F4: ABS
D5: Benceno | E5: Acetato de vinilo | F5: Acetato de n-butilo
D6: Butadieno | E6: Acetona | F6: Acetato de etilo
D7: Buteno-1 | E7: Ácido acético | F7: Caucho acrilonitrilo-butadieno
D8: Butileno | E8: Ácido adípico | F8: Caucho butilo
D9: Etileno | E9: Ácido benzoico | F9: Caucho estireno-butadieno
D10: Metanol | E10: Ácido fórmico | F10: Caucho etileno-propileno
D11: Propileno | E11: Ácido fumárico | F11: Caucho polibutadieno
D12: Sulfuro de carbono | E12: Ácido nítrico | F12: Caucho policloropreno
D13: Tolueno | E13: Ácido salicílico | F13: Caucho poliisopreno
D14: o-Xileno | E14: Ácido tereftálico | F14: Cloruro de amonio
D15: Xilenos mezcla | E15: Acrilonitrilo | F15: Cloruro de metileno
E16: Alcoholes de C7 a C13 | F16: Concentrado urea-formol
E17: Alquilbenceno lineal | F17: Copolímero EVA
E18: Anhídrico ftalico | F18: Dietilenglicol
E19: Anhídrico maleico | F19: Di-isocianato de difenilmetano (MDI)
E20: Bisfenol A | F20: Di-isocianato de tolueno (TDI)
E21: i-Butanol | F21: Éteres glicólicos
E22: n-Butanol | F22: Fosfato diamónico
E23: Butanol secundario | F23: Hexametilentetramina
E24: Butil hidroxi tolueno - BHT | F24: Metacrilato de metilo
E25: Caprolactama | F25: Metil etil cetona
E26: Ciclohexano | F26: Metil isobutil cetona
E27: Cloroformo | F27: Negro de humo
... E45: Propilenglicol | F45: Tetracloroetileno
F46: Tricloroetileno
F47: Urea

Sheet Capacidad instalada ind quim
B2: Capacidad instalada de productos quimicos 2024
B3: Producto Petroquimico | C3: Planta | D3: Ciudad | E3: Provincia | F3: Capacidad instalada activa | G3: Plantas inactivas/cerradas
B4: ÁCIDO SULFÚRICO 98% | C4: MERANOL S.A. | D4: Dock Sud | E4: Buenos Aires | F4: 100000
B5: ÁCIDO SULFÚRICO 98% | C5: FÁBRICA MILITAR RÍO TERCERO | D5: Rio Tercero | E5: Cordoba | F5: 39600
B6: ÁCIDO SULFÚRICO 98% | C6: NOURYON CHEMICALS ARGENTINA S.A.U. | D6: San Lorenzo | E6: Santa Fe | F6: 145000
B7: ÁCIDO SULFÚRICO 98% | C7: AR ZINC S.A. | D7: Fray Luis Beltran | E7: Santa Fe | F7: Cerro | G7: 78000
B8: ÁCIDO SULFÚRICO 98% | C8: MINERA SANTA RITA S.R.L. | D8: Campo Quijano | E8: Salta | F8: 36000
B9: AGUA OXIGENADA 100 % | C9: ATANOR S.C.A. | D9: Rio Tercero | E9: Cordoba | F9: 14400
B10: CARBONATO DE SODIO (Soda Solvay) | C10: ALCALIS DE LA PATAGONIA S.A.I.C. | D10: San Antonio Oeste | E10: Rio Negro | F10: 250000
B11: CAUCHO NATURAL
B12: CLORO | C12: ATANOR S.C.A. | D12: Rio Tercero | E12: Cordoba | F12: 38520
B13: CLORO | C13: TRANSCLOR S.A. | D13: Pilar | E13: Buenos Aires | F13: 149650
B14: CLORO | C14: UNIPAR INDUPA S.A.I.C. | D14: Bahia Blanca | E14: Buenos Aires | F14: 163000
B15: CLORO | C15: Otros | F15: 17000
B16: DIÓXIDO DE TITANIO
B17: FURFURAL | C17: INDUNOR S.A. | D17: La Escondida | E17: Chaco | F17: 3363
B18: HIDRÓXIDO DE SODIO 100 % (Soda Cáustica) | C18: ATANOR S.C.A. | D18: Rio Tercero | E18: Cordoba | F18: 43200
B19: HIDRÓXIDO DE SODIO 100 % (Soda Cáustica) | C19: TRANSCLOR S.A. | D19: Pilar | E19: Buenos Aires | F19: 167608
B20: HIDRÓXIDO DE SODIO 100 % (Soda Cáustica) | C20: UNIPAR INDUPA S.A.I.C. | D20: Bahia Blanca | E20: Buenos Aires | F20: 194000
B21: HIDRÓXIDO DE SODIO 100 % (Soda Cáustica) | C21: Otros | F21: 20000
B22: PARAFINA | C22: YPF S.A. | D22: Ensenada | E22: Buenos Aires | F22: Inactiva | G22: 13000
B23: SUPERFOSFATO SIMPLE DE CALCIO | C23: BUNGE ARGENTINA S.A. | D23: Ramallo | E23: Buenos Aires | F23: 270000
B24: SUPERFOSFATO SIMPLE DE CALCIO | C24: ERMINAL DE FERTILIZANTES ARG. S.A. | D24: Puerto General San Martin | E24: Santa Fe | F24: 220000
B25: TIOSULFATO DE POTASIO | C25: BUNGE ARGENTINA S.A. | D25: Campana | E25: Buenos Aires | F25: 14085
B26: Total | C26: {=COUNTA(_xludf.UNIQUE(_xlws.FILTER(C4:C25,C4:C25<>"")))} -> 1 | D26: {=COUNTA(_xludf.UNIQUE(_xlws.FILTER(D4:D25,D4:D25<>"")))} -> 1 | E26: {=COUNTA(_xludf.UNIQUE(_xlws.FILTER(E4:E25,E4:E25<>"")))} -> 1 | F26: =SUM(F4:F25) -> 1885426 | G26: {=COUNTA(_xludf.UNIQUE(_xlws.FILTER(G4:G25,G4:G25<>"")))} -> 1
